Workbook
Name BG: #REF!
Name BG: #REF!
Name csDesignMode: 1
Name DATA: #REF!
Name DATA: #REF!

Sheet VAC+13th (2)
B1: VACATION ACCRUAL LOCAL EMPLOYEES-FCH 2025 | AG1: 9 | AH1: =+AG1+1 -> 10 | AI1: =+AH1+1 -> 11 | AJ1: =+AI1+1 -> 12 | AK1: =+AJ1+1 -> 13 | AL1: =+AK1+1 -> 14 | AM1: =+AL1+1 -> 15 | AN1: =+AM1+1 -> 16 | AO1: =+AN1+1 -> 17 | ... AS1: =+AR1+1 -> 21
B2: FILL ALL THE CELLS IN GREEN ONLY
A3: 1 | B3: =+A3+1 -> 2 | C3: =+B3+1 -> 3 | D3: 4 | E3: =+D3+1 -> 5 | G3: =+E3+1 -> 6 | H3: =+G3+1 -> 7 | I3: =+H3+1 -> 8 | J3: =+I3+1 -> 9 | K3: =+J3+1 -> 10 | L3: =+K3+1 -> 11 | M3: =+L3+1 -> 12 | N3: =+M3+1 -> 13 | O3: =+N3+1 -> 14 | ... AD3: =+AC3+1 -> 29 | AF3: =+AD3+1 -> 30 | AG3: =+AF3+1 -> 31 | AH3: =+AG3+1 -> 32 | AI3: =+AH3+1 -> 33 | AJ3: =+AI3+1 -> 34 | AK3: =+AJ3+1 -> 35 | AL3: =+AK3+1 -> 36 | AM3: =+AL3+1 -> 37 | AN3: =+AM3+1 -> 38 | ... CJ3: =+CI3+1 -> 86
A4: 1 | B4: -Add new employee names & information | H4: 45647 | R4: DAYS OF THE Month | S4: =+DAY(S6-S5) -> 30 | T4: =+DAY(T6-T5) -> 30 | U4: =+DAY(U6-U5) -> 27 | V4: =+DAY(V6-V5) -> 30 | W4: =+DAY(W6-W5) -> 29 | X4: =+DAY(X6-X5) -> 30 | Y4: =+DAY(Y6-Y5) -> 29 | Z4: =+DAY(Z6-Z5) -> 30 | ... AD4: =+DAY(AD6-AD5) -> 29 | AW4: =+MONTH(AW5) -> 12 | AX4: =+MONTH(AX5) -> 1 | AY4: =+MONTH(AY5) -> 2 | AZ4: =+MONTH(AZ5) -> 3 | BA4: =+MONTH(BA5) -> 4 | BB4: =+MONTH(BB5) -> 5 | BC4: =+MONTH(BC5) -> 6 | BD4: =+MONTH(BD5) -> 7 | ... BH4: =+MONTH(BH5) -> 11 | BJ4: =+MONTH(BJ5) -> 12 | BK4: =+MONTH(BK5) -> 1 | BL4: =+MONTH(BL5) -> 2 | BM4: =+MONTH(BM5) -> 3 | BN4: =+MONTH(BN5) -> 4 | BO4: =+MONTH(BO5) -> 5 | BP4: =+MONTH(BP5) -> 6 | BQ4: =+MONTH(BQ5) -> 7 | ... BU4: =+MONTH(BU5) -> 11
B5: -Don’t' delete names of employee who have left, Just fill the leaving date in cell F | H5: 45677 | S5: 45647 | T5: 45678 | U5: 45709 | V5: 45737 | W5: 45768 | X5: 45798 | Y5: 45829 | Z5: 45859 | AA5: 45890 | AB5: 45921 | AC5: 45951 | AD5: 45982 | AG5: =S5 -> 45647 | AH5: =T5 -> 45678 | AI5: =U5 -> 45709 | AJ5: 45737 | AK5: =W5 -> 45768 | AL5: =X5 -> 45798 | AM5: =Y5 -> 45829 | AN5: =Z5 -> 45859 | AO5: =AA5 -> 45890 | AP5: =AB5 -> 45921 | AQ5: =AC5 -> 45951 | AR5: =AD5 -> 45982 | AW5: =S5 -> 45647 | AX5: =T5 -> 45678 | AY5: =U5 -> 45709 | AZ5: =V5 -> 45737 | BA5: =W5 -> 45768 | BB5: =X5 -> 45798 | BC5: =Y5 -> 45829 | BD5: =Z5 -> 45859 | ... BH5: =AD5 -> 45982 | BJ5: =S5 -> 45647 | BK5: =T5 -> 45678 | BL5: =U5 -> 45709 | BM5: =V5 -> 45737 | BN5: =W5 -> 45768 | BO5: =X5 -> 45798 | BP5: =Y5 -> 45829 | BQ5: =Z5 -> 45859 | ... BU5: =AD5 -> 45982 | BX5: 45658 | BY5: 45689 | BZ5: 45717 | CA5: 45748 | CB5: 45778 | CC5: 45809 | CD5: 45839 | CE5: 45870 | CF5: 45901 | CG5: 45931 | CH5: 45962 | CI5: 45992
A6: ADD | B6: ADD | C6: ADD | E6: ADD | G6: ADD | L6: ADD | O6: ADD | P6: 45658 | S6: 45677 | T6: 45708 | U6: 45736 | V6: 45767 | W6: 45797 | X6: 45828 | Y6: 45858 | Z6: 45889 | AA6: 45920 | AB6: 45950 | AC6: 45981 | AD6: 46011 | AG6: =S6 -> 45677 | AH6: =T6 -> 45708 | AI6: =U6 -> 45736 | AJ6: 43941 | AK6: =W6 -> 45797 | AL6: =X6 -> 45828 | AM6: =Y6 -> 45858 | AN6: =Z6 -> 45889 | AO6: =AA6 -> 45920 | AP6: =AB6 -> 45950 | AQ6: =AC6 -> 45981 | AR6: =AD6 -> 46011 | AU6: 231330 | AW6: =S6 -> 45677 | AX6: =T6 -> 45708 | AY6: =U6 -> 45736 | AZ6: =V6 -> 45767 | BA6: =W6 -> 45797 | BB6: =X6 -> 45828 | BC6: =Y6 -> 45858 | BD6: =Z6 -> 45889 | ... BH6: =AD6 -> 46011 | BI6: 231330 | BJ6: =S6 -> 45677 | BK6: =T6 -> 45708 | BL6: =U6 -> 45736 | BM6: =V6 -> 45767 | BN6: =W6 -> 45797 | BO6: =X6 -> 45828 | BP6: =Y6 -> 45858 | BQ6: =Z6 -> 45889 | ... BU6: =AD6 -> 46011 | BX6: 45688 | BY6: 45716 | BZ6: 45747 | CA6: 45777 | CB6: 45808 | CC6: 45838 | CD6: 45869 | CE6: 45900 | CF6: 45930 | CG6: 45961 | CH6: 45991 | CI6: 46022 | CJ6: 231120
A7: ID | B7: Nom | C7: POSITION | D7: CC | E7: Salaire de base Mensuel | G7: Starting date | H7: Current YEAR Date Prov. | I7: Type | J7: CDI Date | K7: Change Date1 | L7: New Base1 | M7: Change Date2 | N7: New Base2 | O7: Leaving date | P7: 1Day Ancienneté/5Years in Current Year | Q7: VACATION BALANCE 2024 (Days) | R7: TOTAL VACATION ACCRUAL 2025 (Days) | S7: Jan | T7: Feb | U7: Mar | V7: Apr | W7: May | X7: Jun | Y7: Jul | Z7: Aug | AA7: Sep | AB7: Oct | AC7: Nov | AD7: Dec | AE7: 1 | AF7: TOTAL DAYS PAID/FINANCE (25) | AG7: Jan | AH7: Feb | AI7: Mar | AJ7: Apr | AK7: May | AL7: Jun | AM7: Jul | AN7: Aug | AO7: Sep | AP7: Oct | AQ7: Nov | AR7: Dec | AS7: TOTAL BALANCE Days TO PAY 2025 | AU7: TOTAL VACATION BALANCE 2024 ($) | AV7: TOTAL VACATION ACCRUAL 2025($) | AW7: Jan | AX7: Feb | AY7: Mar | AZ7: Apr | BA7: May | BB7: Jun | BC7: Jul | BD7: Aug | BE7: Sep | BF7: Oct | BG7: Nov | BH7: Dec | BI7: $ TAKEN (Reversal) | BJ7: Jan | BK7: Feb | BL7: Mar | BM7: Apr | BN7: May | BO7: Jun | BP7: Jul | BQ7: Aug | BR7: Sep | BS7: Oct | BT7: Nov | BU7: Dec | BV7: TOTAL BALANCE $ 2025 231330 | BW7: 1 | BX7: Jan | BY7: Feb | BZ7: Mar | CA7: Apr | CB7: May | CC7: Jun | CD7: Jul | CE7: Aug | CF7: Sep | CG7: Oct | CH7: Nov | CI7: Dec | CJ7: TOTAL 13th Month BALANCE 2025 ($) | CK7: DAYS/YEAR | CM7: Salaire de base
A8: 03035 | B8: KIWIDI SALABISALA CHRISTIAN | C8: Income Auditor | D8: =+VLOOKUP(A8,'[1]BDD-Avk Tx'!B:CE,82,0) -> 620 | E8: 634.4 | G8: 41563 | H8: =+IF(YEAR(G8)<YEAR($H$5),$H$4,G8) -> 45647 | I8: =+VLOOKUP(A8,'[1]BDD-Avk Tx'!B:BZ,77,0) -> CDI | J8: =+IF(I8="CDI",H8,H8+0) -> 45647 | P8: =DATEDIF(G8,$AD$6,"m")/12 -> 12.166667 | Q8: 64 | R8: =SUM(S8:AD8) -> 20 | S8: =+IF(AND(AND($O8="",$P8>=10,MONTH($G8)=MONTH(S$5))),1.5+2,+IF(AND(AND($O8="",$P8>=5,MONTH($G8)=MONTH(S$5))),1.5+1,+IF(AND(AND($P8=5,$O8="",MONTH($G8)=MONTH(S$5))),1.5,+IF(AND($H8>S$5,MONTH($H8)=MONTH(S$5)),1.5/30*(S$4-DAY($H8)),+IF(AND(MONTH($H8)<MONTH(S$5),$O8=""),1.5,+IF(AND($H8=$S$5,$O8=""),1.5,IF($O8<S$5,0,IF(MONTH($O8)=MONTH(S$5),1.5/30*($O8-S$5),1.5)))))))) -> 1.5 | T8: =+IF(AND(AND($O8="",$P8>=10,MONTH($G8)=MONTH(T$5))),1.5+2,+IF(AND(AND($O8="",$P8>=5,MONTH($G8)=MONTH(T$5))),1.5+1,+IF(AND(AND($P8=5,$O8="",MONTH($G8)=MONTH(T$5))),1.5,+IF(AND($H8>T$5,MONTH($H8)=MONTH(T$5)),1.5/30*(T$4-DAY($H8)),+IF(AND(MONTH($H8)<MONTH(T$5),$O8=""),1.5,+IF(AND($H8=$S$5,$O8=""),1.5,IF($O8<T$5,0,IF(MONTH($O8)=MONTH(T$5),1.5/30*($O8-T$5),1.5)))))))) -> 1.5 | U8: =+IF(AND(AND($O8="",$P8>=10,MONTH($G8)=MONTH(U$5))),1.5+2,+IF(AND(AND($O8="",$P8>=5,MONTH($G8)=MONTH(U$5))),1.5+1,+IF(AND(AND($P8=5,$O8="",MONTH($G8)=MONTH(U$5))),1.5,+IF(AND($H8>U$5,MONTH($H8)=MONTH(U$5)),1.5/30*(U$4-DAY($H8)),+IF(AND(MONTH($H8)<MONTH(U$5),$O8=""),1.5,+IF(AND($H8=$S$5,$O8=""),1.5,IF($O8<U$5,0,IF(MONTH($O8)=MONTH(U$5),1.5/30*($O8-U$5),1.5)))))))) -> 1.5 | V8: =+IF(AND(AND($O8="",$P8>=10,MONTH($G8)=MONTH(V$5))),1.5+2,+IF(AND(AND($O8="",$P8>=5,MONTH($G8)=MONTH(V$5))),1.5+1,+IF(AND(AND($P8=5,$O8="",MONTH($G8)=MONTH(V$5))),1.5,+IF(AND($H8>V$5,MONTH($H8)=MONTH(V$5)),1.5/30*(V$4-DAY($H8)),+IF(AND(MONTH($H8)<MONTH(V$5),$O8=""),1.5,+IF(AND($H8=$S$5,$O8=""),1.5,IF($O8<V$5,0,IF(MONTH($O8)=MONTH(V$5),1.5/30*($O8-V$5),1.5)))))))) -> 1.5 | W8: =+IF(AND(AND($O8="",$P8>=10,MONTH($G8)=MONTH(W$5))),1.5+2,+IF(AND(AND($O8="",$P8>=5,MONTH($G8)=MONTH(W$5))),1.5+1,+IF(AND(AND($P8=5,$O8="",MONTH($G8)=MONTH(W$5))),1.5,+IF(AND($H8>W$5,MONTH($H8)=MONTH(W$5)),1.5/30*(W$4-DAY($H8)),+IF(AND(MONTH($H8)<MONTH(W$5),$O8=""),1.5,+IF(AND($H8=$S$5,$O8=""),1.5,IF($O8<W$5,0,IF(MONTH($O8)=MONTH(W$5),1.5/30*($O8-W$5),1.5)))))))) -> 1.5 | X8: =+IF(AND(AND($O8="",$P8>=10,MONTH($G8)=MONTH(X$5))),1.5+2,+IF(AND(AND($O8="",$P8>=5,MONTH($G8)=MONTH(X$5))),1.5+1,+IF(AND(AND($P8=5,$O8="",MONTH($G8)=MONTH(X$5))),1.5,+IF(AND($H8>X$5,MONTH($H8)=MONTH(X$5)),1.5/30*(X$4-DAY($H8)),+IF(AND(MONTH($H8)<MONTH(X$5),$O8=""),1.5,+IF(AND($H8=$S$5,$O8=""),1.5,IF($O8<X$5,0,IF(MONTH($O8)=MONTH(X$5),1.5/30*($O8-X$5),1.5)))))))) -> 1.5 | Y8: =+IF(AND(AND($O8="",$P8>=10,MONTH($G8)=MONTH(Y$5))),1.5+2,+IF(AND(AND($O8="",$P8>=5,MONTH($G8)=MONTH(Y$5))),1.5+1,+IF(AND(AND($P8=5,$O8="",MONTH($G8)=MONTH(Y$5))),1.5,+IF(AND($H8>Y$5,MONTH($H8)=MONTH(Y$5)),1.5/30*(Y$4-DAY($H8)),+IF(AND(MONTH($H8)<MONTH(Y$5),$O8=""),1.5,+IF(AND($H8=$S$5,$O8=""),1.5,IF($O8<Y$5,0,IF(MONTH($O8)=MONTH(Y$5),1.5/30*($O8-Y$5),1.5)))))))) -> 1.5 | Z8: =+IF(AND(AND($O8="",$P8>=10,MONTH($G8)=MONTH(Z$5))),1.5+2,+IF(AND(AND($O8="",$P8>=5,MONTH($G8)=MONTH(Z$5))),1.5+1,+IF(AND(AND($P8=5,$O8="",MONTH($G8)=MONTH(Z$5))),1.5,+IF(AND($H8>Z$5,MONTH($H8)=MONTH(Z$5)),1.5/30*(Z$4-DAY($H8)),+IF(AND(MONTH($H8)<MONTH(Z$5),$O8=""),1.5,+IF(AND($H8=$S$5,$O8=""),1.5,IF($O8<Z$5,0,IF(MONTH($O8)=MONTH(Z$5),1.5/30*($O8-Z$5),1.5)))))))) -> 1.5 | ... AD8: =+IF(AND(AND($O8="",$P8>=10,MONTH($G8)=MONTH(AD$5))),1.5+2,+IF(AND(AND($O8="",$P8>=5,MONTH($G8)=MONTH(AD$5))),1.5+1,+IF(AND(AND($P8=5,$O8="",MONTH($G8)=MONTH(AD$5))),1.5,+IF(AND($H8>AD$5,MONTH($H8)=MONTH(AD$5)),1.5/30*(AD$4-DAY($H8)),+IF(AND(MONTH($H8)<MONTH(AD$5),$O8=""),1.5,+IF(AND($H8=$S$5,$O8=""),1.5,IF($O8<AD$5,0,IF(MONTH($O8)=MONTH(AD$5),1.5/30*($O8-AD$5),1.5)))))))) -> 1.5 | AF8: =SUM(AG8:AR8) -> 0 | AG8: 0 | AH8: 0 | AI8: 0 | AS8: =+Q8+R8-AF8 -> 84 | AU8: 1223.4385 | AV8: =SUM(AW8:BH8) -> 488 | AW8: =+IF($K8="",$E8/26*S8,IF(MONTH($K8)=MONTH(AW$5),$L8/26*S8,IF(AND($K8<AW$5,(MONTH($K8)<>MONTH(AW$5))),$L8/26*S8,$E8/26*S8))) -> 36.6 | AX8: =+IF($K8="",$E8/26*T8,IF(MONTH($K8)=MONTH(AX$5),$L8/26*T8,IF(AND($K8<AX$5,(MONTH($K8)<>MONTH(AX$5))),$L8/26*T8,$E8/26*T8))) -> 36.6 | AY8: =+IF($K8="",$E8/26*U8,IF(MONTH($K8)=MONTH(AY$5),$L8/26*U8,IF(AND($K8<AY$5,(MONTH($K8)<>MONTH(AY$5))),$L8/26*U8,$E8/26*U8))) -> 36.6 | AZ8: =+IF($K8="",$E8/26*V8,IF(MONTH($K8)=MONTH(AZ$5),$L8/26*V8,IF(AND($K8<AZ$5,(MONTH($K8)<>MONTH(AZ$5))),$L8/26*V8,$E8/26*V8))) -> 36.6 | BA8: =+IF($K8="",$E8/26*W8,IF(MONTH($K8)=MONTH(BA$5),$L8/26*W8,IF(AND($K8<BA$5,(MONTH($K8)<>MONTH(BA$5))),$L8/26*W8,$E8/26*W8))) -> 36.6 | BB8: =+IF($K8="",$E8/26*X8,IF(MONTH($K8)=MONTH(BB$5),$L8/26*X8,IF(AND($K8<BB$5,(MONTH($K8)<>MONTH(BB$5))),$L8/26*X8,$E8/26*X8))) -> 36.6 | BC8: =+IF($K8="",$E8/26*Y8,IF(MONTH($K8)=MONTH(BC$5),$L8/26*Y8,IF(AND($K8<BC$5,(MONTH($K8)<>MONTH(BC$5))),$L8/26*Y8,$E8/26*Y8))) -> 36.6 | BD8: =+IF($K8="",$E8/26*Z8,IF(MONTH($K8)=MONTH(BD$5),$L8/26*Z8,IF(AND($K8<BD$5,(MONTH($K8)<>MONTH(BD$5))),$L8/26*Z8,$E8/26*Z8))) -> 36.6 | ... BH8: =+IF($K8="",$E8/26*AD8,IF(MONTH($K8)=MONTH(BH$5),$L8/26*AD8,IF(AND($K8<BH$5,(MONTH($K8)<>MONTH(BH$5))),$L8/26*AD8,$E8/26*AD8))) -> 36.6 | BI8: =SUM(BJ8:BU8) -> 0 | BJ8: =(+IF($K8="",$E8/26*AG8,IF(MONTH($K8)=MONTH(BJ$5),$L8/26*AG8,IF(AND($K8<BJ$5,(MONTH($K8)<>MONTH(BJ$5))),$L8/26*AG8,$E8/26*AG8))))*-1 -> 0 | BK8: =(+IF($K8="",$E8/26*AH8,IF(MONTH($K8)=MONTH(BK$5),$L8/26*AH8,IF(AND($K8<BK$5,(MONTH($K8)<>MONTH(BK$5))),$L8/26*AH8,$E8/26*AH8))))*-1 -> 0 | BL8: =(+IF($K8="",$E8/26*AI8,IF(MONTH($K8)=MONTH(BL$5),$L8/26*AI8,IF(AND($K8<BL$5,(MONTH($K8)<>MONTH(BL$5))),$L8/26*AI8,$E8/26*AI8))))*-1 -> 0 | BM8: =(+IF($K8="",$E8/26*AJ8,IF(MONTH($K8)=MONTH(BM$5),$L8/26*AJ8,IF(AND($K8<BM$5,(MONTH($K8)<>MONTH(BM$5))),$L8/26*AJ8,$E8/26*AJ8))))*-1 -> 0 | BN8: =(+IF($K8="",$E8/26*AK8,IF(MONTH($K8)=MONTH(BN$5),$L8/26*AK8,IF(AND($K8<BN$5,(MONTH($K8)<>MONTH(BN$5))),$L8/26*AK8,$E8/26*AK8))))*-1 -> 0 | BO8: =(+IF($K8="",$E8/26*AL8,IF(MONTH($K8)=MONTH(BO$5),$L8/26*AL8,IF(AND($K8<BO$5,(MONTH($K8)<>MONTH(BO$5))),$L8/26*AL8,$E8/26*AL8))))*-1 -> 0 | BP8: =(+IF($K8="",$E8/26*AM8,IF(MONTH($K8)=MONTH(BP$5),$L8/26*AM8,IF(AND($K8<BP$5,(MONTH($K8)<>MONTH(BP$5))),$L8/26*AM8,$E8/26*AM8))))*-1 -> 0 | BQ8: =(+IF($K8="",$E8/26*AN8,IF(MONTH($K8)=MONTH(BQ$5),$L8/26*AN8,IF(AND($K8<BQ$5,(MONTH($K8)<>MONTH(BQ$5))),$L8/26*AN8,$E8/26*AN8))))*-1 -> 0 | ... BU8: =(+IF($K8="",$E8/26*AR8,IF(MONTH($K8)=MONTH(BU$5),$L8/26*AR8,IF(AND($K8<BU$5,(MONTH($K8)<>MONTH(BU$5))),$L8/26*AR8,$E8/26*AR8))))*-1 -> 0 | BV8: =+AU8+AV8+BI8 -> 1711.4385 | BX8: =+IF(AND($J8>BX$5,MONTH($J8<>BX$5)),0,+IF(AND($J8>BX$5,MONTH($J8=BX$5)),$E8/$R8*DAY($J8),IF(AND($O8<>"",$O8<BX$5),0,IF($K8="",$E8/$R8*S8,IF(MONTH($K8)=MONTH(BX$5),$L8/$R8*S8,IF(AND($K8<BX$5,(MONTH($K8)<>MONTH(BX$5))),$L8/$R8*S8,$E8/$R8*S8)))))) -> 47.58 | BY8: =+IF(AND($J8>BY$5,MONTH($J8<>BY$5)),0,+IF(AND($J8>BY$5,MONTH($J8=BY$5)),$E8/$R8*DAY($J8),IF(AND($O8<>"",$O8<BY$5),0,IF($K8="",$E8/$R8*T8,IF(MONTH($K8)=MONTH(BY$5),$L8/$R8*T8,IF(AND($K8<BY$5,(MONTH($K8)<>MONTH(BY$5))),$L8/$R8*T8,$E8/$R8*T8)))))) -> 47.58 | BZ8: =+IF(AND($J8>BZ$5,MONTH($J8<>BZ$5)),0,+IF(AND($J8>BZ$5,MONTH($J8=BZ$5)),$E8/$R8*DAY($J8),IF(AND($O8<>"",$O8<BZ$5),0,IF($K8="",$E8/$R8*U8,IF(MONTH($K8)=MONTH(BZ$5),$L8/$R8*U8,IF(AND($K8<BZ$5,(MONTH($K8)<>MONTH(BZ$5))),$L8/$R8*U8,$E8/$R8*U8)))))) -> 47.58 | CA8: =+IF(AND($J8>CA$5,MONTH($J8<>CA$5)),0,+IF(AND($J8>CA$5,MONTH($J8=CA$5)),$E8/$R8*DAY($J8),IF(AND($O8<>"",$O8<CA$5),0,IF($K8="",$E8/$R8*V8,IF(MONTH($K8)=MONTH(CA$5),$L8/$R8*V8,IF(AND($K8<CA$5,(MONTH($K8)<>MONTH(CA$5))),$L8/$R8*V8,$E8/$R8*V8)))))) -> 47.58 | CB8: =+IF(AND($J8>CB$5,MONTH($J8<>CB$5)),0,+IF(AND($J8>CB$5,MONTH($J8=CB$5)),$E8/$R8*DAY($J8),IF(AND($O8<>"",$O8<CB$5),0,IF($K8="",$E8/$R8*W8,IF(MONTH($K8)=MONTH(CB$5),$L8/$R8*W8,IF(AND($K8<CB$5,(MONTH($K8)<>MONTH(CB$5))),$L8/$R8*W8,$E8/$R8*W8)))))) -> 47.58 | CC8: =+IF(AND($J8>CC$5,MONTH($J8<>CC$5)),0,+IF(AND($J8>CC$5,MONTH($J8=CC$5)),$E8/$R8*DAY($J8),IF(AND($O8<>"",$O8<CC$5),0,IF($K8="",$E8/$R8*X8,IF(MONTH($K8)=MONTH(CC$5),$L8/$R8*X8,IF(AND($K8<CC$5,(MONTH($K8)<>MONTH(CC$5))),$L8/$R8*X8,$E8/$R8*X8)))))) -> 47.58 | CD8: =+IF(AND($J8>CD$5,MONTH($J8<>CD$5)),0,+IF(AND($J8>CD$5,MONTH($J8=CD$5)),$E8/$R8*DAY($J8),IF(AND($O8<>"",$O8<CD$5),0,IF($K8="",$E8/$R8*Y8,IF(MONTH($K8)=MONTH(CD$5),$L8/$R8*Y8,IF(AND($K8<CD$5,(MONTH($K8)<>MONTH(CD$5))),$L8/$R8*Y8,$E8/$R8*Y8)))))) -> 47.58 | CE8: =+IF(AND($J8>CE$5,MONTH($J8<>CE$5)),0,+IF(AND($J8>CE$5,MONTH($J8=CE$5)),$E8/$R8*DAY($J8),IF(AND($O8<>"",$O8<CE$5),0,IF($K8="",$E8/$R8*Z8,IF(MONTH($K8)=MONTH(CE$5),$L8/$R8*Z8,IF(AND($K8<CE$5,(MONTH($K8)<>MONTH(CE$5))),$L8/$R8*Z8,$E8/$R8*Z8)))))) -> 47.58 | ... CI8: =+IF(AND($J8>CI$5,MONTH($J8<>CI$5)),0,+IF(AND($J8>CI$5,MONTH($J8=CI$5)),$E8/$R8*DAY($J8),IF(AND($O8<>"",$O8<CI$5),0,IF($K8="",$E8/$R8*AD8,IF(MONTH($K8)=MONTH(CI$5),$L8/$R8*AD8,IF(AND($K8<CI$5,(MONTH($K8)<>MONTH(CI$5))),$L8/$R8*AD8,$E8/$R8*AD8)))))) -> 47.58 | CJ8: =SUM(BX8:CI8) -> 634.4 | CK8: =+IF(P8<5,18,IF(AND(P8>=5,P8<10),19,IF(AND(P8>=10,P8<15),20,IF(AND(P8>=15,P8<20),21,0)))) -> 20 | CL8: =+CM8-CJ8 -> 0 | CM8: =IF(L8=0,E8,(L8-E8+E8)) -> 634.4
A9: 03047 | B9: KITENGIE KAPENGA GAUTHIER | C9: Credit Manager | D9: =+VLOOKUP(A9,'[1]BDD-Avk Tx'!B:CE,82,0) -> 620 | E9: 1323 | G9: 42065 | H9: =+IF(YEAR(G9)<YEAR($H$5),$H$4,G9) -> 45647 | I9: =+VLOOKUP(A9,'[1]BDD-Avk Tx'!B:BZ,77,0) -> CDI | J9: =+IF(I9="CDI",H9,H9+0) -> 45647 | P9: =DATEDIF(G9,$AD$6,"m")/12 -> 10.75 | Q9: 38 | R9: =SUM(S9:AD9) -> 20 | S9: =+IF(AND(AND($O9="",$P9>=10,MONTH($G9)=MONTH(S$5))),1.5+2,+IF(AND(AND($O9="",$P9>=5,MONTH($G9)=MONTH(S$5))),1.5+1,+IF(AND(AND($P9=5,$O9="",MONTH($G9)=MONTH(S$5))),1.5,+IF(AND($H9>S$5,MONTH($H9)=MONTH(S$5)),1.5/30*(S$4-DAY($H9)),+IF(AND(MONTH($H9)<MONTH(S$5),$O9=""),1.5,+IF(AND($H9=$S$5,$O9=""),1.5,IF($O9<S$5,0,IF(MONTH($O9)=MONTH(S$5),1.5/30*($O9-S$5),1.5)))))))) -> 1.5 | T9: =+IF(AND(AND($O9="",$P9>=10,MONTH($G9)=MONTH(T$5))),1.5+2,+IF(AND(AND($O9="",$P9>=5,MONTH($G9)=MONTH(T$5))),1.5+1,+IF(AND(AND($P9=5,$O9="",MONTH($G9)=MONTH(T$5))),1.5,+IF(AND($H9>T$5,MONTH($H9)=MONTH(T$5)),1.5/30*(T$4-DAY($H9)),+IF(AND(MONTH($H9)<MONTH(T$5),$O9=""),1.5,+IF(AND($H9=$S$5,$O9=""),1.5,IF($O9<T$5,0,IF(MONTH($O9)=MONTH(T$5),1.5/30*($O9-T$5),1.5)))))))) -> 1.5 | U9: =+IF(AND(AND($O9="",$P9>=10,MONTH($G9)=MONTH(U$5))),1.5+2,+IF(AND(AND($O9="",$P9>=5,MONTH($G9)=MONTH(U$5))),1.5+1,+IF(AND(AND($P9=5,$O9="",MONTH($G9)=MONTH(U$5))),1.5,+IF(AND($H9>U$5,MONTH($H9)=MONTH(U$5)),1.5/30*(U$4-DAY($H9)),+IF(AND(MONTH($H9)<MONTH(U$5),$O9=""),1.5,+IF(AND($H9=$S$5,$O9=""),1.5,IF($O9<U$5,0,IF(MONTH($O9)=MONTH(U$5),1.5/30*($O9-U$5),1.5)))))))) -> 1.5 | V9: =+IF(AND(AND($O9="",$P9>=10,MONTH($G9)=MONTH(V$5))),1.5+2,+IF(AND(AND($O9="",$P9>=5,MONTH($G9)=MONTH(V$5))),1.5+1,+IF(AND(AND($P9=5,$O9="",MONTH($G9)=MONTH(V$5))),1.5,+IF(AND($H9>V$5,MONTH($H9)=MONTH(V$5)),1.5/30*(V$4-DAY($H9)),+IF(AND(MONTH($H9)<MONTH(V$5),$O9=""),1.5,+IF(AND($H9=$S$5,$O9=""),1.5,IF($O9<V$5,0,IF(MONTH($O9)=MONTH(V$5),1.5/30*($O9-V$5),1.5)))))))) -> 3.5 | W9: =+IF(AND(AND($O9="",$P9>=10,MONTH($G9)=MONTH(W$5))),1.5+2,+IF(AND(AND($O9="",$P9>=5,MONTH($G9)=MONTH(W$5))),1.5+1,+IF(AND(AND($P9=5,$O9="",MONTH($G9)=MONTH(W$5))),1.5,+IF(AND($H9>W$5,MONTH($H9)=MONTH(W$5)),1.5/30*(W$4-DAY($H9)),+IF(AND(MONTH($H9)<MONTH(W$5),$O9=""),1.5,+IF(AND($H9=$S$5,$O9=""),1.5,IF($O9<W$5,0,IF(MONTH($O9)=MONTH(W$5),1.5/30*($O9-W$5),1.5)))))))) -> 1.5 | X9: =+IF(AND(AND($O9="",$P9>=10,MONTH($G9)=MONTH(X$5))),1.5+2,+IF(AND(AND($O9="",$P9>=5,MONTH($G9)=MONTH(X$5))),1.5+1,+IF(AND(AND($P9=5,$O9="",MONTH($G9)=MONTH(X$5))),1.5,+IF(AND($H9>X$5,MONTH($H9)=MONTH(X$5)),1.5/30*(X$4-DAY($H9)),+IF(AND(MONTH($H9)<MONTH(X$5),$O9=""),1.5,+IF(AND($H9=$S$5,$O9=""),1.5,IF($O9<X$5,0,IF(MONTH($O9)=MONTH(X$5),1.5/30*($O9-X$5),1.5)))))))) -> 1.5 | Y9: =+IF(AND(AND($O9="",$P9>=10,MONTH($G9)=MONTH(Y$5))),1.5+2,+IF(AND(AND($O9="",$P9>=5,MONTH($G9)=MONTH(Y$5))),1.5+1,+IF(AND(AND($P9=5,$O9="",MONTH($G9)=MONTH(Y$5))),1.5,+IF(AND($H9>Y$5,MONTH($H9)=MONTH(Y$5)),1.5/30*(Y$4-DAY($H9)),+IF(AND(MONTH($H9)<MONTH(Y$5),$O9=""),1.5,+IF(AND($H9=$S$5,$O9=""),1.5,IF($O9<Y$5,0,IF(MONTH($O9)=MONTH(Y$5),1.5/30*($O9-Y$5),1.5)))))))) -> 1.5 | Z9: =+IF(AND(AND($O9="",$P9>=10,MONTH($G9)=MONTH(Z$5))),1.5+2,+IF(AND(AND($O9="",$P9>=5,MONTH($G9)=MONTH(Z$5))),1.5+1,+IF(AND(AND($P9=5,$O9="",MONTH($G9)=MONTH(Z$5))),1.5,+IF(AND($H9>Z$5,MONTH($H9)=MONTH(Z$5)),1.5/30*(Z$4-DAY($H9)),+IF(AND(MONTH($H9)<MONTH(Z$5),$O9=""),1.5,+IF(AND($H9=$S$5,$O9=""),1.5,IF($O9<Z$5,0,IF(MONTH($O9)=MONTH(Z$5),1.5/30*($O9-Z$5),1.5)))))))) -> 1.5 | ... AD9: =+IF(AND(AND($O9="",$P9>=10,MONTH($G9)=MONTH(AD$5))),1.5+2,+IF(AND(AND($O9="",$P9>=5,MONTH($G9)=MONTH(AD$5))),1.5+1,+IF(AND(AND($P9=5,$O9="",MONTH($G9)=MONTH(AD$5))),1.5,+IF(AND($H9>AD$5,MONTH($H9)=MONTH(AD$5)),1.5/30*(AD$4-DAY($H9)),+IF(AND(MONTH($H9)<MONTH(AD$5),$O9=""),1.5,+IF(AND($H9=$S$5,$O9=""),1.5,IF($O9<AD$5,0,IF(MONTH($O9)=MONTH(AD$5),1.5/30*($O9-AD$5),1.5)))))))) -> 1.5 | AF9: =SUM(AG9:AR9) -> 0 | AG9: 0 | AH9: 0 | AI9: 0 | AS9: =+Q9+R9-AF9 -> 58 | AU9: 1933.6154 | AV9: =SUM(AW9:BH9) -> 1017.6923 | AW9: =+IF($K9="",$E9/26*S9,IF(MONTH($K9)=MONTH(AW$5),$L9/26*S9,IF(AND($K9<AW$5,(MONTH($K9)<>MONTH(AW$5))),$L9/26*S9,$E9/26*S9))) -> 76.326923 | AX9: =+IF($K9="",$E9/26*T9,IF(MONTH($K9)=MONTH(AX$5),$L9/26*T9,IF(AND($K9<AX$5,(MONTH($K9)<>MONTH(AX$5))),$L9/26*T9,$E9/26*T9))) -> 76.326923 | AY9: =+IF($K9="",$E9/26*U9,IF(MONTH($K9)=MONTH(AY$5),$L9/26*U9,IF(AND($K9<AY$5,(MONTH($K9)<>MONTH(AY$5))),$L9/26*U9,$E9/26*U9))) -> 76.326923 | AZ9: =+IF($K9="",$E9/26*V9,IF(MONTH($K9)=MONTH(AZ$5),$L9/26*V9,IF(AND($K9<AZ$5,(MONTH($K9)<>MONTH(AZ$5))),$L9/26*V9,$E9/26*V9))) -> 178.09615 | BA9: =+IF($K9="",$E9/26*W9,IF(MONTH($K9)=MONTH(BA$5),$L9/26*W9,IF(AND($K9<BA$5,(MONTH($K9)<>MONTH(BA$5))),$L9/26*W9,$E9/26*W9))) -> 76.326923 | BB9: =+IF($K9="",$E9/26*X9,IF(MONTH($K9)=MONTH(BB$5),$L9/26*X9,IF(AND($K9<BB$5,(MONTH($K9)<>MONTH(BB$5))),$L9/26*X9,$E9/26*X9))) -> 76.326923 | BC9: =+IF($K9="",$E9/26*Y9,IF(MONTH($K9)=MONTH(BC$5),$L9/26*Y9,IF(AND($K9<BC$5,(MONTH($K9)<>MONTH(BC$5))),$L9/26*Y9,$E9/26*Y9))) -> 76.326923 | BD9: =+IF($K9="",$E9/26*Z9,IF(MONTH($K9)=MONTH(BD$5),$L9/26*Z9,IF(AND($K9<BD$5,(MONTH($K9)<>MONTH(BD$5))),$L9/26*Z9,$E9/26*Z9))) -> 76.326923 | ... BH9: =+IF($K9="",$E9/26*AD9,IF(MONTH($K9)=MONTH(BH$5),$L9/26*AD9,IF(AND($K9<BH$5,(MONTH($K9)<>MONTH(BH$5))),$L9/26*AD9,$E9/26*AD9))) -> 76.326923 | BI9: =SUM(BJ9:BU9) -> 0 | BJ9: =(+IF($K9="",$E9/26*AG9,IF(MONTH($K9)=MONTH(BJ$5),$L9/26*AG9,IF(AND($K9<BJ$5,(MONTH($K9)<>MONTH(BJ$5))),$L9/26*AG9,$E9/26*AG9))))*-1 -> 0 | BK9: =(+IF($K9="",$E9/26*AH9,IF(MONTH($K9)=MONTH(BK$5),$L9/26*AH9,IF(AND($K9<BK$5,(MONTH($K9)<>MONTH(BK$5))),$L9/26*AH9,$E9/26*AH9))))*-1 -> 0 | BL9: =(+IF($K9="",$E9/26*AI9,IF(MONTH($K9)=MONTH(BL$5),$L9/26*AI9,IF(AND($K9<BL$5,(MONTH($K9)<>MONTH(BL$5))),$L9/26*AI9,$E9/26*AI9))))*-1 -> 0 | BM9: =(+IF($K9="",$E9/26*AJ9,IF(MONTH($K9)=MONTH(BM$5),$L9/26*AJ9,IF(AND($K9<BM$5,(MONTH($K9)<>MONTH(BM$5))),$L9/26*AJ9,$E9/26*AJ9))))*-1 -> 0 | BN9: =(+IF($K9="",$E9/26*AK9,IF(MONTH($K9)=MONTH(BN$5),$L9/26*AK9,IF(AND($K9<BN$5,(MONTH($K9)<>MONTH(BN$5))),$L9/26*AK9,$E9/26*AK9))))*-1 -> 0 | BO9: =(+IF($K9="",$E9/26*AL9,IF(MONTH($K9)=MONTH(BO$5),$L9/26*AL9,IF(AND($K9<BO$5,(MONTH($K9)<>MONTH(BO$5))),$L9/26*AL9,$E9/26*AL9))))*-1 -> 0 | BP9: =(+IF($K9="",$E9/26*AM9,IF(MONTH($K9)=MONTH(BP$5),$L9/26*AM9,IF(AND($K9<BP$5,(MONTH($K9)<>MONTH(BP$5))),$L9/26*AM9,$E9/26*AM9))))*-1 -> 0 | BQ9: =(+IF($K9="",$E9/26*AN9,IF(MONTH($K9)=MONTH(BQ$5),$L9/26*AN9,IF(AND($K9<BQ$5,(MONTH($K9)<>MONTH(BQ$5))),$L9/26*AN9,$E9/26*AN9))))*-1 -> 0 | ... BU9: =(+IF($K9="",$E9/26*AR9,IF(MONTH($K9)=MONTH(BU$5),$L9/26*AR9,IF(AND($K9<BU$5,(MONTH($K9)<>MONTH(BU$5))),$L9/26*AR9,$E9/26*AR9))))*-1 -> 0 | BV9: =+AU9+AV9+BI9 -> 2951.3077 | BX9: =+IF(AND($J9>BX$5,MONTH($J9<>BX$5)),0,+IF(AND($J9>BX$5,MONTH($J9=BX$5)),$E9/$R9*DAY($J9),IF(AND($O9<>"",$O9<BX$5),0,IF($K9="",$E9/$R9*S9,IF(MONTH($K9)=MONTH(BX$5),$L9/$R9*S9,IF(AND($K9<BX$5,(MONTH($K9)<>MONTH(BX$5))),$L9/$R9*S9,$E9/$R9*S9)))))) -> 99.225 | BY9: =+IF(AND($J9>BY$5,MONTH($J9<>BY$5)),0,+IF(AND($J9>BY$5,MONTH($J9=BY$5)),$E9/$R9*DAY($J9),IF(AND($O9<>"",$O9<BY$5),0,IF($K9="",$E9/$R9*T9,IF(MONTH($K9)=MONTH(BY$5),$L9/$R9*T9,IF(AND($K9<BY$5,(MONTH($K9)<>MONTH(BY$5))),$L9/$R9*T9,$E9/$R9*T9)))))) -> 99.225 | BZ9: =+IF(AND($J9>BZ$5,MONTH($J9<>BZ$5)),0,+IF(AND($J9>BZ$5,MONTH($J9=BZ$5)),$E9/$R9*DAY($J9),IF(AND($O9<>"",$O9<BZ$5),0,IF($K9="",$E9/$R9*U9,IF(MONTH($K9)=MONTH(BZ$5),$L9/$R9*U9,IF(AND($K9<BZ$5,(MONTH($K9)<>MONTH(BZ$5))),$L9/$R9*U9,$E9/$R9*U9)))))) -> 99.225 | CA9: =+IF(AND($J9>CA$5,MONTH($J9<>CA$5)),0,+IF(AND($J9>CA$5,MONTH($J9=CA$5)),$E9/$R9*DAY($J9),IF(AND($O9<>"",$O9<CA$5),0,IF($K9="",$E9/$R9*V9,IF(MONTH($K9)=MONTH(CA$5),$L9/$R9*V9,IF(AND($K9<CA$5,(MONTH($K9)<>MONTH(CA$5))),$L9/$R9*V9,$E9/$R9*V9)))))) -> 231.525 | CB9: =+IF(AND($J9>CB$5,MONTH($J9<>CB$5)),0,+IF(AND($J9>CB$5,MONTH($J9=CB$5)),$E9/$R9*DAY($J9),IF(AND($O9<>"",$O9<CB$5),0,IF($K9="",$E9/$R9*W9,IF(MONTH($K9)=MONTH(CB$5),$L9/$R9*W9,IF(AND($K9<CB$5,(MONTH($K9)<>MONTH(CB$5))),$L9/$R9*W9,$E9/$R9*W9)))))) -> 99.225 | CC9: =+IF(AND($J9>CC$5,MONTH($J9<>CC$5)),0,+IF(AND($J9>CC$5,MONTH($J9=CC$5)),$E9/$R9*DAY($J9),IF(AND($O9<>"",$O9<CC$5),0,IF($K9="",$E9/$R9*X9,IF(MONTH($K9)=MONTH(CC$5),$L9/$R9*X9,IF(AND($K9<CC$5,(MONTH($K9)<>MONTH(CC$5))),$L9/$R9*X9,$E9/$R9*X9)))))) -> 99.225 | CD9: =+IF(AND($J9>CD$5,MONTH($J9<>CD$5)),0,+IF(AND($J9>CD$5,MONTH($J9=CD$5)),$E9/$R9*DAY($J9),IF(AND($O9<>"",$O9<CD$5),0,IF($K9="",$E9/$R9*Y9,IF(MONTH($K9)=MONTH(CD$5),$L9/$R9*Y9,IF(AND($K9<CD$5,(MONTH($K9)<>MONTH(CD$5))),$L9/$R9*Y9,$E9/$R9*Y9)))))) -> 99.225 | CE9: =+IF(AND($J9>CE$5,MONTH($J9<>CE$5)),0,+IF(AND($J9>CE$5,MONTH($J9=CE$5)),$E9/$R9*DAY($J9),IF(AND($O9<>"",$O9<CE$5),0,IF($K9="",$E9/$R9*Z9,IF(MONTH($K9)=MONTH(CE$5),$L9/$R9*Z9,IF(AND($K9<CE$5,(MONTH($K9)<>MONTH(CE$5))),$L9/$R9*Z9,$E9/$R9*Z9)))))) -> 99.225 | ... CI9: =+IF(AND($J9>CI$5,MONTH($J9<>CI$5)),0,+IF(AND($J9>CI$5,MONTH($J9=CI$5)),$E9/$R9*DAY($J9),IF(AND($O9<>"",$O9<CI$5),0,IF($K9="",$E9/$R9*AD9,IF(MONTH($K9)=MONTH(CI$5),$L9/$R9*AD9,IF(AND($K9<CI$5,(MONTH($K9)<>MONTH(CI$5))),$L9/$R9*AD9,$E9/$R9*AD9)))))) -> 99.225 | CJ9: =SUM(BX9:CI9) -> 1323 | CK9: =+IF(P9<5,18,IF(AND(P9>=5,P9<10),19,IF(AND(P9>=10,P9<15),20,IF(AND(P9>=15,P9<20),21,0)))) -> 20 | CL9: =+CM9-CJ9 -> 0 | CM9: =IF(L9=0,E9,(L9-E9+E9)) -> 1323
A10: 04209 | B10: NGANI ANGONO STEPHANIE | C10: Payroll Accountant | D10: =+VLOOKUP(A10,'[1]BDD-Avk Tx'!B:CE,82,0) -> 620 | E10: 1128.4 | G10: 41201 | H10: =+IF(YEAR(G10)<YEAR($H$5),$H$4,G10) -> 45647 | I10: =+VLOOKUP(A10,'[1]BDD-Avk Tx'!B:BZ,77,0) -> CDI | J10: =+IF(I10="CDI",H10,H10+0) -> 45647 | P10: =DATEDIF(G10,$AD$6,"m")/12 -> 13.166667 | Q10: 6 | R10: =SUM(S10:AD10) -> 20 | S10: =+IF(AND(AND($O10="",$P10>=10,MONTH($G10)=MONTH(S$5))),1.5+2,+IF(AND(AND($O10="",$P10>=5,MONTH($G10)=MONTH(S$5))),1.5+1,+IF(AND(AND($P10=5,$O10="",MONTH($G10)=MONTH(S$5))),1.5,+IF(AND($H10>S$5,MONTH($H10)=MONTH(S$5)),1.5/30*(S$4-DAY($H10)),+IF(AND(MONTH($H10)<MONTH(S$5),$O10=""),1.5,+IF(AND($H10=$S$5,$O10=""),1.5,IF($O10<S$5,0,IF(MONTH($O10)=MONTH(S$5),1.5/30*($O10-S$5),1.5)))))))) -> 1.5 | T10: =+IF(AND(AND($O10="",$P10>=10,MONTH($G10)=MONTH(T$5))),1.5+2,+IF(AND(AND($O10="",$P10>=5,MONTH($G10)=MONTH(T$5))),1.5+1,+IF(AND(AND($P10=5,$O10="",MONTH($G10)=MONTH(T$5))),1.5,+IF(AND($H10>T$5,MONTH($H10)=MONTH(T$5)),1.5/30*(T$4-DAY($H10)),+IF(AND(MONTH($H10)<MONTH(T$5),$O10=""),1.5,+IF(AND($H10=$S$5,$O10=""),1.5,IF($O10<T$5,0,IF(MONTH($O10)=MONTH(T$5),1.5/30*($O10-T$5),1.5)))))))) -> 1.5 | U10: =+IF(AND(AND($O10="",$P10>=10,MONTH($G10)=MONTH(U$5))),1.5+2,+IF(AND(AND($O10="",$P10>=5,MONTH($G10)=MONTH(U$5))),1.5+1,+IF(AND(AND($P10=5,$O10="",MONTH($G10)=MONTH(U$5))),1.5,+IF(AND($H10>U$5,MONTH($H10)=MONTH(U$5)),1.5/30*(U$4-DAY($H10)),+IF(AND(MONTH($H10)<MONTH(U$5),$O10=""),1.5,+IF(AND($H10=$S$5,$O10=""),1.5,IF($O10<U$5,0,IF(MONTH($O10)=MONTH(U$5),1.5/30*($O10-U$5),1.5)))))))) -> 1.5 | V10: =+IF(AND(AND($O10="",$P10>=10,MONTH($G10)=MONTH(V$5))),1.5+2,+IF(AND(AND($O10="",$P10>=5,MONTH($G10)=MONTH(V$5))),1.5+1,+IF(AND(AND($P10=5,$O10="",MONTH($G10)=MONTH(V$5))),1.5,+IF(AND($H10>V$5,MONTH($H10)=MONTH(V$5)),1.5/30*(V$4-DAY($H10)),+IF(AND(MONTH($H10)<MONTH(V$5),$O10=""),1.5,+IF(AND($H10=$S$5,$O10=""),1.5,IF($O10<V$5,0,IF(MONTH($O10)=MONTH(V$5),1.5/30*($O10-V$5),1.5)))))))) -> 1.5 | W10: =+IF(AND(AND($O10="",$P10>=10,MONTH($G10)=MONTH(W$5))),1.5+2,+IF(AND(AND($O10="",$P10>=5,MONTH($G10)=MONTH(W$5))),1.5+1,+IF(AND(AND($P10=5,$O10="",MONTH($G10)=MONTH(W$5))),1.5,+IF(AND($H10>W$5,MONTH($H10)=MONTH(W$5)),1.5/30*(W$4-DAY($H10)),+IF(AND(MONTH($H10)<MONTH(W$5),$O10=""),1.5,+IF(AND($H10=$S$5,$O10=""),1.5,IF($O10<W$5,0,IF(MONTH($O10)=MONTH(W$5),1.5/30*($O10-W$5),1.5)))))))) -> 1.5 | X10: =+IF(AND(AND($O10="",$P10>=10,MONTH($G10)=MONTH(X$5))),1.5+2,+IF(AND(AND($O10="",$P10>=5,MONTH($G10)=MONTH(X$5))),1.5+1,+IF(AND(AND($P10=5,$O10="",MONTH($G10)=MONTH(X$5))),1.5,+IF(AND($H10>X$5,MONTH($H10)=MONTH(X$5)),1.5/30*(X$4-DAY($H10)),+IF(AND(MONTH($H10)<MONTH(X$5),$O10=""),1.5,+IF(AND($H10=$S$5,$O10=""),1.5,IF($O10<X$5,0,IF(MONTH($O10)=MONTH(X$5),1.5/30*($O10-X$5),1.5)))))))) -> 1.5 | Y10: =+IF(AND(AND($O10="",$P10>=10,MONTH($G10)=MONTH(Y$5))),1.5+2,+IF(AND(AND($O10="",$P10>=5,MONTH($G10)=MONTH(Y$5))),1.5+1,+IF(AND(AND($P10=5,$O10="",MONTH($G10)=MONTH(Y$5))),1.5,+IF(AND($H10>Y$5,MONTH($H10)=MONTH(Y$5)),1.5/30*(Y$4-DAY($H10)),+IF(AND(MONTH($H10)<MONTH(Y$5),$O10=""),1.5,+IF(AND($H10=$S$5,$O10=""),1.5,IF($O10<Y$5,0,IF(MONTH($O10)=MONTH(Y$5),1.5/30*($O10-Y$5),1.5)))))))) -> 1.5 | Z10: =+IF(AND(AND($O10="",$P10>=10,MONTH($G10)=MONTH(Z$5))),1.5+2,+IF(AND(AND($O10="",$P10>=5,MONTH($G10)=MONTH(Z$5))),1.5+1,+IF(AND(AND($P10=5,$O10="",MONTH($G10)=MONTH(Z$5))),1.5,+IF(AND($H10>Z$5,MONTH($H10)=MONTH(Z$5)),1.5/30*(Z$4-DAY($H10)),+IF(AND(MONTH($H10)<MONTH(Z$5),$O10=""),1.5,+IF(AND($H10=$S$5,$O10=""),1.5,IF($O10<Z$5,0,IF(MONTH($O10)=MONTH(Z$5),1.5/30*($O10-Z$5),1.5)))))))) -> 1.5 | ... AD10: =+IF(AND(AND($O10="",$P10>=10,MONTH($G10)=MONTH(AD$5))),1.5+2,+IF(AND(AND($O10="",$P10>=5,MONTH($G10)=MONTH(AD$5))),1.5+1,+IF(AND(AND($P10=5,$O10="",MONTH($G10)=MONTH(AD$5))),1.5,+IF(AND($H10>AD$5,MONTH($H10)=MONTH(AD$5)),1.5/30*(AD$4-DAY($H10)),+IF(AND(MONTH($H10)<MONTH(AD$5),$O10=""),1.5,+IF(AND($H10=$S$5,$O10=""),1.5,IF($O10<AD$5,0,IF(MONTH($O10)=MONTH(AD$5),1.5/30*($O10-AD$5),1.5)))))))) -> 1.5 | AF10: =SUM(AG10:AR10) -> 5 | AG10: 0 | AH10: 4 | AI10: 1 | AS10: =+Q10+R10-AF10 -> 21 | AU10: 239.92308 | AV10: =SUM(AW10:BH10) -> 868 | AW10: =+IF($K10="",$E10/26*S10,IF(MONTH($K10)=MONTH(AW$5),$L10/26*S10,IF(AND($K10<AW$5,(MONTH($K10)<>MONTH(AW$5))),$L10/26*S10,$E10/26*S10))) -> 65.1 | AX10: =+IF($K10="",$E10/26*T10,IF(MONTH($K10)=MONTH(AX$5),$L10/26*T10,IF(AND($K10<AX$5,(MONTH($K10)<>MONTH(AX$5))),$L10/26*T10,$E10/26*T10))) -> 65.1 | AY10: =+IF($K10="",$E10/26*U10,IF(MONTH($K10)=MONTH(AY$5),$L10/26*U10,IF(AND($K10<AY$5,(MONTH($K10)<>MONTH(AY$5))),$L10/26*U10,$E10/26*U10))) -> 65.1 | AZ10: =+IF($K10="",$E10/26*V10,IF(MONTH($K10)=MONTH(AZ$5),$L10/26*V10,IF(AND($K10<AZ$5,(MONTH($K10)<>MONTH(AZ$5))),$L10/26*V10,$E10/26*V10))) -> 65.1 | BA10: =+IF($K10="",$E10/26*W10,IF(MONTH($K10)=MONTH(BA$5),$L10/26*W10,IF(AND($K10<BA$5,(MONTH($K10)<>MONTH(BA$5))),$L10/26*W10,$E10/26*W10))) -> 65.1 | BB10: =+IF($K10="",$E10/26*X10,IF(MONTH($K10)=MONTH(BB$5),$L10/26*X10,IF(AND($K10<BB$5,(MONTH($K10)<>MONTH(BB$5))),$L10/26*X10,$E10/26*X10))) -> 65.1 | BC10: =+IF($K10="",$E10/26*Y10,IF(MONTH($K10)=MONTH(BC$5),$L10/26*Y10,IF(AND($K10<BC$5,(MONTH($K10)<>MONTH(BC$5))),$L10/26*Y10,$E10/26*Y10))) -> 65.1 | BD10: =+IF($K10="",$E10/26*Z10,IF(MONTH($K10)=MONTH(BD$5),$L10/26*Z10,IF(AND($K10<BD$5,(MONTH($K10)<>MONTH(BD$5))),$L10/26*Z10,$E10/26*Z10))) -> 65.1 | ... BH10: =+IF($K10="",$E10/26*AD10,IF(MONTH($K10)=MONTH(BH$5),$L10/26*AD10,IF(AND($K10<BH$5,(MONTH($K10)<>MONTH(BH$5))),$L10/26*AD10,$E10/26*AD10))) -> 65.1 | BI10: =SUM(BJ10:BU10) -> -217 | BJ10: =(+IF($K10="",$E10/26*AG10,IF(MONTH($K10)=MONTH(BJ$5),$L10/26*AG10,IF(AND($K10<BJ$5,(MONTH($K10)<>MONTH(BJ$5))),$L10/26*AG10,$E10/26*AG10))))*-1 -> 0 | BK10: =(+IF($K10="",$E10/26*AH10,IF(MONTH($K10)=MONTH(BK$5),$L10/26*AH10,IF(AND($K10<BK$5,(MONTH($K10)<>MONTH(BK$5))),$L10/26*AH10,$E10/26*AH10))))*-1 -> -173.6 | BL10: =(+IF($K10="",$E10/26*AI10,IF(MONTH($K10)=MONTH(BL$5),$L10/26*AI10,IF(AND($K10<BL$5,(MONTH($K10)<>MONTH(BL$5))),$L10/26*AI10,$E10/26*AI10))))*-1 -> -43.4 | BM10: =(+IF($K10="",$E10/26*AJ10,IF(MONTH($K10)=MONTH(BM$5),$L10/26*AJ10,IF(AND($K10<BM$5,(MONTH($K10)<>MONTH(BM$5))),$L10/26*AJ10,$E10/26*AJ10))))*-1 -> 0 | BN10: =(+IF($K10="",$E10/26*AK10,IF(MONTH($K10)=MONTH(BN$5),$L10/26*AK10,IF(AND($K10<BN$5,(MONTH($K10)<>MONTH(BN$5))),$L10/26*AK10,$E10/26*AK10))))*-1 -> 0 | BO10: =(+IF($K10="",$E10/26*AL10,IF(MONTH($K10)=MONTH(BO$5),$L10/26*AL10,IF(AND($K10<BO$5,(MONTH($K10)<>MONTH(BO$5))),$L10/26*AL10,$E10/26*AL10))))*-1 -> 0 | BP10: =(+IF($K10="",$E10/26*AM10,IF(MONTH($K10)=MONTH(BP$5),$L10/26*AM10,IF(AND($K10<BP$5,(MONTH($K10)<>MONTH(BP$5))),$L10/26*AM10,$E10/26*AM10))))*-1 -> 0 | BQ10: =(+IF($K10="",$E10/26*AN10,IF(MONTH($K10)=MONTH(BQ$5),$L10/26*AN10,IF(AND($K10<BQ$5,(MONTH($K10)<>MONTH(BQ$5))),$L10/26*AN10,$E10/26*AN10))))*-1 -> 0 | ... BU10: =(+IF($K10="",$E10/26*AR10,IF(MONTH($K10)=MONTH(BU$5),$L10/26*AR10,IF(AND($K10<BU$5,(MONTH($K10)<>MONTH(BU$5))),$L10/26*AR10,$E10/26*AR10))))*-1 -> 0 | BV10: =+AU10+AV10+BI10 -> 890.92308 | BX10: =+IF(AND($J10>BX$5,MONTH($J10<>BX$5)),0,+IF(AND($J10>BX$5,MONTH($J10=BX$5)),$E10/$R10*DAY($J10),IF(AND($O10<>"",$O10<BX$5),0,IF($K10="",$E10/$R10*S10,IF(MONTH($K10)=MONTH(BX$5),$L10/$R10*S10,IF(AND($K10<BX$5,(MONTH($K10)<>MONTH(BX$5))),$L10/$R10*S10,$E10/$R10*S10)))))) -> 84.63 | BY10: =+IF(AND($J10>BY$5,MONTH($J10<>BY$5)),0,+IF(AND($J10>BY$5,MONTH($J10=BY$5)),$E10/$R10*DAY($J10),IF(AND($O10<>"",$O10<BY$5),0,IF($K10="",$E10/$R10*T10,IF(MONTH($K10)=MONTH(BY$5),$L10/$R10*T10,IF(AND($K10<BY$5,(MONTH($K10)<>MONTH(BY$5))),$L10/$R10*T10,$E10/$R10*T10)))))) -> 84.63 | BZ10: =+IF(AND($J10>BZ$5,MONTH($J10<>BZ$5)),0,+IF(AND($J10>BZ$5,MONTH($J10=BZ$5)),$E10/$R10*DAY($J10),IF(AND($O10<>"",$O10<BZ$5),0,IF($K10="",$E10/$R10*U10,IF(MONTH($K10)=MONTH(BZ$5),$L10/$R10*U10,IF(AND($K10<BZ$5,(MONTH($K10)<>MONTH(BZ$5))),$L10/$R10*U10,$E10/$R10*U10)))))) -> 84.63 | CA10: =+IF(AND($J10>CA$5,MONTH($J10<>CA$5)),0,+IF(AND($J10>CA$5,MONTH($J10=CA$5)),$E10/$R10*DAY($J10),IF(AND($O10<>"",$O10<CA$5),0,IF($K10="",$E10/$R10*V10,IF(MONTH($K10)=MONTH(CA$5),$L10/$R10*V10,IF(AND($K10<CA$5,(MONTH($K10)<>MONTH(CA$5))),$L10/$R10*V10,$E10/$R10*V10)))))) -> 84.63 | CB10: =+IF(AND($J10>CB$5,MONTH($J10<>CB$5)),0,+IF(AND($J10>CB$5,MONTH($J10=CB$5)),$E10/$R10*DAY($J10),IF(AND($O10<>"",$O10<CB$5),0,IF($K10="",$E10/$R10*W10,IF(MONTH($K10)=MONTH(CB$5),$L10/$R10*W10,IF(AND($K10<CB$5,(MONTH($K10)<>MONTH(CB$5))),$L10/$R10*W10,$E10/$R10*W10)))))) -> 84.63 | CC10: =+IF(AND($J10>CC$5,MONTH($J10<>CC$5)),0,+IF(AND($J10>CC$5,MONTH($J10=CC$5)),$E10/$R10*DAY($J10),IF(AND($O10<>"",$O10<CC$5),0,IF($K10="",$E10/$R10*X10,IF(MONTH($K10)=MONTH(CC$5),$L10/$R10*X10,IF(AND($K10<CC$5,(MONTH($K10)<>MONTH(CC$5))),$L10/$R10*X10,$E10/$R10*X10)))))) -> 84.63 | CD10: =+IF(AND($J10>CD$5,MONTH($J10<>CD$5)),0,+IF(AND($J10>CD$5,MONTH($J10=CD$5)),$E10/$R10*DAY($J10),IF(AND($O10<>"",$O10<CD$5),0,IF($K10="",$E10/$R10*Y10,IF(MONTH($K10)=MONTH(CD$5),$L10/$R10*Y10,IF(AND($K10<CD$5,(MONTH($K10)<>MONTH(CD$5))),$L10/$R10*Y10,$E10/$R10*Y10)))))) -> 84.63 | CE10: =+IF(AND($J10>CE$5,MONTH($J10<>CE$5)),0,+IF(AND($J10>CE$5,MONTH($J10=CE$5)),$E10/$R10*DAY($J10),IF(AND($O10<>"",$O10<CE$5),0,IF($K10="",$E10/$R10*Z10,IF(MONTH($K10)=MONTH(CE$5),$L10/$R10*Z10,IF(AND($K10<CE$5,(MONTH($K10)<>MONTH(CE$5))),$L10/$R10*Z10,$E10/$R10*Z10)))))) -> 84.63 | ... CI10: =+IF(AND($J10>CI$5,MONTH($J10<>CI$5)),0,+IF(AND($J10>CI$5,MONTH($J10=CI$5)),$E10/$R10*DAY($J10),IF(AND($O10<>"",$O10<CI$5),0,IF($K10="",$E10/$R10*AD10,IF(MONTH($K10)=MONTH(CI$5),$L10/$R10*AD10,IF(AND($K10<CI$5,(MONTH($K10)<>MONTH(CI$5))),$L10/$R10*AD10,$E10/$R10*AD10)))))) -> 84.63 | CJ10: =SUM(BX10:CI10) -> 1128.4 | CK10: =+IF(P10<5,18,IF(AND(P10>=5,P10<10),19,IF(AND(P10>=10,P10<15),20,IF(AND(P10>=15,P10<20),21,0)))) -> 20 | CL10: =+CM10-CJ10 -> 0 | CM10: =IF(L10=0,E10,(L10-E10+E10)) -> 1128.4
A11: 04019 | B11: MAKUNTIMA MAMBUENE COUCOU | C11: Concierge Supervisor | D11: =+VLOOKUP(A11,'[1]BDD-Avk Tx'!B:CE,82,0) -> 120 | E11: 231.4 | G11: 41153 | H11: =+IF(YEAR(G11)<YEAR($H$5),$H$4,G11) -> 45647 | I11: =+VLOOKUP(A11,'[1]BDD-Avk Tx'!B:BZ,77,0) -> CDI | J11: =+IF(I11="CDI",H11,H11+0) -> 45647 | P11: =DATEDIF(G11,$AD$6,"m")/12 -> 13.25 | Q11: 13 | R11: =SUM(S11:AD11) -> 20 | S11: =+IF(AND(AND($O11="",$P11>=10,MONTH($G11)=MONTH(S$5))),1.5+2,+IF(AND(AND($O11="",$P11>=5,MONTH($G11)=MONTH(S$5))),1.5+1,+IF(AND(AND($P11=5,$O11="",MONTH($G11)=MONTH(S$5))),1.5,+IF(AND($H11>S$5,MONTH($H11)=MONTH(S$5)),1.5/30*(S$4-DAY($H11)),+IF(AND(MONTH($H11)<MONTH(S$5),$O11=""),1.5,+IF(AND($H11=$S$5,$O11=""),1.5,IF($O11<S$5,0,IF(MONTH($O11)=MONTH(S$5),1.5/30*($O11-S$5),1.5)))))))) -> 1.5 | T11: =+IF(AND(AND($O11="",$P11>=10,MONTH($G11)=MONTH(T$5))),1.5+2,+IF(AND(AND($O11="",$P11>=5,MONTH($G11)=MONTH(T$5))),1.5+1,+IF(AND(AND($P11=5,$O11="",MONTH($G11)=MONTH(T$5))),1.5,+IF(AND($H11>T$5,MONTH($H11)=MONTH(T$5)),1.5/30*(T$4-DAY($H11)),+IF(AND(MONTH($H11)<MONTH(T$5),$O11=""),1.5,+IF(AND($H11=$S$5,$O11=""),1.5,IF($O11<T$5,0,IF(MONTH($O11)=MONTH(T$5),1.5/30*($O11-T$5),1.5)))))))) -> 1.5 | U11: =+IF(AND(AND($O11="",$P11>=10,MONTH($G11)=MONTH(U$5))),1.5+2,+IF(AND(AND($O11="",$P11>=5,MONTH($G11)=MONTH(U$5))),1.5+1,+IF(AND(AND($P11=5,$O11="",MONTH($G11)=MONTH(U$5))),1.5,+IF(AND($H11>U$5,MONTH($H11)=MONTH(U$5)),1.5/30*(U$4-DAY($H11)),+IF(AND(MONTH($H11)<MONTH(U$5),$O11=""),1.5,+IF(AND($H11=$S$5,$O11=""),1.5,IF($O11<U$5,0,IF(MONTH($O11)=MONTH(U$5),1.5/30*($O11-U$5),1.5)))))))) -> 1.5 | V11: =+IF(AND(AND($O11="",$P11>=10,MONTH($G11)=MONTH(V$5))),1.5+2,+IF(AND(AND($O11="",$P11>=5,MONTH($G11)=MONTH(V$5))),1.5+1,+IF(AND(AND($P11=5,$O11="",MONTH($G11)=MONTH(V$5))),1.5,+IF(AND($H11>V$5,MONTH($H11)=MONTH(V$5)),1.5/30*(V$4-DAY($H11)),+IF(AND(MONTH($H11)<MONTH(V$5),$O11=""),1.5,+IF(AND($H11=$S$5,$O11=""),1.5,IF($O11<V$5,0,IF(MONTH($O11)=MONTH(V$5),1.5/30*($O11-V$5),1.5)))))))) -> 1.5 | W11: =+IF(AND(AND($O11="",$P11>=10,MONTH($G11)=MONTH(W$5))),1.5+2,+IF(AND(AND($O11="",$P11>=5,MONTH($G11)=MONTH(W$5))),1.5+1,+IF(AND(AND($P11=5,$O11="",MONTH($G11)=MONTH(W$5))),1.5,+IF(AND($H11>W$5,MONTH($H11)=MONTH(W$5)),1.5/30*(W$4-DAY($H11)),+IF(AND(MONTH($H11)<MONTH(W$5),$O11=""),1.5,+IF(AND($H11=$S$5,$O11=""),1.5,IF($O11<W$5,0,IF(MONTH($O11)=MONTH(W$5),1.5/30*($O11-W$5),1.5)))))))) -> 1.5 | X11: =+IF(AND(AND($O11="",$P11>=10,MONTH($G11)=MONTH(X$5))),1.5+2,+IF(AND(AND($O11="",$P11>=5,MONTH($G11)=MONTH(X$5))),1.5+1,+IF(AND(AND($P11=5,$O11="",MONTH($G11)=MONTH(X$5))),1.5,+IF(AND($H11>X$5,MONTH($H11)=MONTH(X$5)),1.5/30*(X$4-DAY($H11)),+IF(AND(MONTH($H11)<MONTH(X$5),$O11=""),1.5,+IF(AND($H11=$S$5,$O11=""),1.5,IF($O11<X$5,0,IF(MONTH($O11)=MONTH(X$5),1.5/30*($O11-X$5),1.5)))))))) -> 1.5 | Y11: =+IF(AND(AND($O11="",$P11>=10,MONTH($G11)=MONTH(Y$5))),1.5+2,+IF(AND(AND($O11="",$P11>=5,MONTH($G11)=MONTH(Y$5))),1.5+1,+IF(AND(AND($P11=5,$O11="",MONTH($G11)=MONTH(Y$5))),1.5,+IF(AND($H11>Y$5,MONTH($H11)=MONTH(Y$5)),1.5/30*(Y$4-DAY($H11)),+IF(AND(MONTH($H11)<MONTH(Y$5),$O11=""),1.5,+IF(AND($H11=$S$5,$O11=""),1.5,IF($O11<Y$5,0,IF(MONTH($O11)=MONTH(Y$5),1.5/30*($O11-Y$5),1.5)))))))) -> 1.5 | Z11: =+IF(AND(AND($O11="",$P11>=10,MONTH($G11)=MONTH(Z$5))),1.5+2,+IF(AND(AND($O11="",$P11>=5,MONTH($G11)=MONTH(Z$5))),1.5+1,+IF(AND(AND($P11=5,$O11="",MONTH($G11)=MONTH(Z$5))),1.5,+IF(AND($H11>Z$5,MONTH($H11)=MONTH(Z$5)),1.5/30*(Z$4-DAY($H11)),+IF(AND(MONTH($H11)<MONTH(Z$5),$O11=""),1.5,+IF(AND($H11=$S$5,$O11=""),1.5,IF($O11<Z$5,0,IF(MONTH($O11)=MONTH(Z$5),1.5/30*($O11-Z$5),1.5)))))))) -> 1.5 | ... AD11: =+IF(AND(AND($O11="",$P11>=10,MONTH($G11)=MONTH(AD$5))),1.5+2,+IF(AND(AND($O11="",$P11>=5,MONTH($G11)=MONTH(AD$5))),1.5+1,+IF(AND(AND($P11=5,$O11="",MONTH($G11)=MONTH(AD$5))),1.5,+IF(AND($H11>AD$5,MONTH($H11)=MONTH(AD$5)),1.5/30*(AD$4-DAY($H11)),+IF(AND(MONTH($H11)<MONTH(AD$5),$O11=""),1.5,+IF(AND($H11=$S$5,$O11=""),1.5,IF($O11<AD$5,0,IF(MONTH($O11)=MONTH(AD$5),1.5/30*($O11-AD$5),1.5)))))))) -> 1.5 | AF11: =SUM(AG11:AR11) -> 14 | AG11: 0 | AH11: 0 | AI11: 14 | AS11: =+Q11+R11-AF11 -> 19 | AU11: 110.59231 | AV11: =SUM(AW11:BH11) -> 178 | AW11: =+IF($K11="",$E11/26*S11,IF(MONTH($K11)=MONTH(AW$5),$L11/26*S11,IF(AND($K11<AW$5,(MONTH($K11)<>MONTH(AW$5))),$L11/26*S11,$E11/26*S11))) -> 13.35 | AX11: =+IF($K11="",$E11/26*T11,IF(MONTH($K11)=MONTH(AX$5),$L11/26*T11,IF(AND($K11<AX$5,(MONTH($K11)<>MONTH(AX$5))),$L11/26*T11,$E11/26*T11))) -> 13.35 | AY11: =+IF($K11="",$E11/26*U11,IF(MONTH($K11)=MONTH(AY$5),$L11/26*U11,IF(AND($K11<AY$5,(MONTH($K11)<>MONTH(AY$5))),$L11/26*U11,$E11/26*U11))) -> 13.35 | AZ11: =+IF($K11="",$E11/26*V11,IF(MONTH($K11)=MONTH(AZ$5),$L11/26*V11,IF(AND($K11<AZ$5,(MONTH($K11)<>MONTH(AZ$5))),$L11/26*V11,$E11/26*V11))) -> 13.35 | BA11: =+IF($K11="",$E11/26*W11,IF(MONTH($K11)=MONTH(BA$5),$L11/26*W11,IF(AND($K11<BA$5,(MONTH($K11)<>MONTH(BA$5))),$L11/26*W11,$E11/26*W11))) -> 13.35 | BB11: =+IF($K11="",$E11/26*X11,IF(MONTH($K11)=MONTH(BB$5),$L11/26*X11,IF(AND($K11<BB$5,(MONTH($K11)<>MONTH(BB$5))),$L11/26*X11,$E11/26*X11))) -> 13.35 | BC11: =+IF($K11="",$E11/26*Y11,IF(MONTH($K11)=MONTH(BC$5),$L11/26*Y11,IF(AND($K11<BC$5,(MONTH($K11)<>MONTH(BC$5))),$L11/26*Y11,$E11/26*Y11))) -> 13.35 | BD11: =+IF($K11="",$E11/26*Z11,IF(MONTH($K11)=MONTH(BD$5),$L11/26*Z11,IF(AND($K11<BD$5,(MONTH($K11)<>MONTH(BD$5))),$L11/26*Z11,$E11/26*Z11))) -> 13.35 | ... BH11: =+IF($K11="",$E11/26*AD11,IF(MONTH($K11)=MONTH(BH$5),$L11/26*AD11,IF(AND($K11<BH$5,(MONTH($K11)<>MONTH(BH$5))),$L11/26*AD11,$E11/26*AD11))) -> 13.35 | BI11: =SUM(BJ11:BU11) -> -124.6 | BJ11: =(+IF($K11="",$E11/26*AG11,IF(MONTH($K11)=MONTH(BJ$5),$L11/26*AG11,IF(AND($K11<BJ$5,(MONTH($K11)<>MONTH(BJ$5))),$L11/26*AG11,$E11/26*AG11))))*-1 -> 0 | BK11: =(+IF($K11="",$E11/26*AH11,IF(MONTH($K11)=MONTH(BK$5),$L11/26*AH11,IF(AND($K11<BK$5,(MONTH($K11)<>MONTH(BK$5))),$L11/26*AH11,$E11/26*AH11))))*-1 -> 0 | BL11: =(+IF($K11="",$E11/26*AI11,IF(MONTH($K11)=MONTH(BL$5),$L11/26*AI11,IF(AND($K11<BL$5,(MONTH($K11)<>MONTH(BL$5))),$L11/26*AI11,$E11/26*AI11))))*-1 -> -124.6 | BM11: =(+IF($K11="",$E11/26*AJ11,IF(MONTH($K11)=MONTH(BM$5),$L11/26*AJ11,IF(AND($K11<BM$5,(MONTH($K11)<>MONTH(BM$5))),$L11/26*AJ11,$E11/26*AJ11))))*-1 -> 0 | BN11: =(+IF($K11="",$E11/26*AK11,IF(MONTH($K11)=MONTH(BN$5),$L11/26*AK11,IF(AND($K11<BN$5,(MONTH($K11)<>MONTH(BN$5))),$L11/26*AK11,$E11/26*AK11))))*-1 -> 0 | BO11: =(+IF($K11="",$E11/26*AL11,IF(MONTH($K11)=MONTH(BO$5),$L11/26*AL11,IF(AND($K11<BO$5,(MONTH($K11)<>MONTH(BO$5))),$L11/26*AL11,$E11/26*AL11))))*-1 -> 0 | BP11: =(+IF($K11="",$E11/26*AM11,IF(MONTH($K11)=MONTH(BP$5),$L11/26*AM11,IF(AND($K11<BP$5,(MONTH($K11)<>MONTH(BP$5))),$L11/26*AM11,$E11/26*AM11))))*-1 -> 0 | BQ11: =(+IF($K11="",$E11/26*AN11,IF(MONTH($K11)=MONTH(BQ$5),$L11/26*AN11,IF(AND($K11<BQ$5,(MONTH($K11)<>MONTH(BQ$5))),$L11/26*AN11,$E11/26*AN11))))*-1 -> 0 | ... BU11: =(+IF($K11="",$E11/26*AR11,IF(MONTH($K11)=MONTH(BU$5),$L11/26*AR11,IF(AND($K11<BU$5,(MONTH($K11)<>MONTH(BU$5))),$L11/26*AR11,$E11/26*AR11))))*-1 -> 0 | BV11: =+AU11+AV11+BI11 -> 163.99231 | BX11: =+IF(AND($J11>BX$5,MONTH($J11<>BX$5)),0,+IF(AND($J11>BX$5,MONTH($J11=BX$5)),$E11/$R11*DAY($J11),IF(AND($O11<>"",$O11<BX$5),0,IF($K11="",$E11/$R11*S11,IF(MONTH($K11)=MONTH(BX$5),$L11/$R11*S11,IF(AND($K11<BX$5,(MONTH($K11)<>MONTH(BX$5))),$L11/$R11*S11,$E11/$R11*S11)))))) -> 17.355 | BY11: =+IF(AND($J11>BY$5,MONTH($J11<>BY$5)),0,+IF(AND($J11>BY$5,MONTH($J11=BY$5)),$E11/$R11*DAY($J11),IF(AND($O11<>"",$O11<BY$5),0,IF($K11="",$E11/$R11*T11,IF(MONTH($K11)=MONTH(BY$5),$L11/$R11*T11,IF(AND($K11<BY$5,(MONTH($K11)<>MONTH(BY$5))),$L11/$R11*T11,$E11/$R11*T11)))))) -> 17.355 | BZ11: =+IF(AND($J11>BZ$5,MONTH($J11<>BZ$5)),0,+IF(AND($J11>BZ$5,MONTH($J11=BZ$5)),$E11/$R11*DAY($J11),IF(AND($O11<>"",$O11<BZ$5),0,IF($K11="",$E11/$R11*U11,IF(MONTH($K11)=MONTH(BZ$5),$L11/$R11*U11,IF(AND($K11<BZ$5,(MONTH($K11)<>MONTH(BZ$5))),$L11/$R11*U11,$E11/$R11*U11)))))) -> 17.355 | CA11: =+IF(AND($J11>CA$5,MONTH($J11<>CA$5)),0,+IF(AND($J11>CA$5,MONTH($J11=CA$5)),$E11/$R11*DAY($J11),IF(AND($O11<>"",$O11<CA$5),0,IF($K11="",$E11/$R11*V11,IF(MONTH($K11)=MONTH(CA$5),$L11/$R11*V11,IF(AND($K11<CA$5,(MONTH($K11)<>MONTH(CA$5))),$L11/$R11*V11,$E11/$R11*V11)))))) -> 17.355 | CB11: =+IF(AND($J11>CB$5,MONTH($J11<>CB$5)),0,+IF(AND($J11>CB$5,MONTH($J11=CB$5)),$E11/$R11*DAY($J11),IF(AND($O11<>"",$O11<CB$5),0,IF($K11="",$E11/$R11*W11,IF(MONTH($K11)=MONTH(CB$5),$L11/$R11*W11,IF(AND($K11<CB$5,(MONTH($K11)<>MONTH(CB$5))),$L11/$R11*W11,$E11/$R11*W11)))))) -> 17.355 | CC11: =+IF(AND($J11>CC$5,MONTH($J11<>CC$5)),0,+IF(AND($J11>CC$5,MONTH($J11=CC$5)),$E11/$R11*DAY($J11),IF(AND($O11<>"",$O11<CC$5),0,IF($K11="",$E11/$R11*X11,IF(MONTH($K11)=MONTH(CC$5),$L11/$R11*X11,IF(AND($K11<CC$5,(MONTH($K11)<>MONTH(CC$5))),$L11/$R11*X11,$E11/$R11*X11)))))) -> 17.355 | CD11: =+IF(AND($J11>CD$5,MONTH($J11<>CD$5)),0,+IF(AND($J11>CD$5,MONTH($J11=CD$5)),$E11/$R11*DAY($J11),IF(AND($O11<>"",$O11<CD$5),0,IF($K11="",$E11/$R11*Y11,IF(MONTH($K11)=MONTH(CD$5),$L11/$R11*Y11,IF(AND($K11<CD$5,(MONTH($K11)<>MONTH(CD$5))),$L11/$R11*Y11,$E11/$R11*Y11)))))) -> 17.355 | CE11: =+IF(AND($J11>CE$5,MONTH($J11<>CE$5)),0,+IF(AND($J11>CE$5,MONTH($J11=CE$5)),$E11/$R11*DAY($J11),IF(AND($O11<>"",$O11<CE$5),0,IF($K11="",$E11/$R11*Z11,IF(MONTH($K11)=MONTH(CE$5),$L11/$R11*Z11,IF(AND($K11<CE$5,(MONTH($K11)<>MONTH(CE$5))),$L11/$R11*Z11,$E11/$R11*Z11)))))) -> 17.355 | ... CI11: =+IF(AND($J11>CI$5,MONTH($J11<>CI$5)),0,+IF(AND($J11>CI$5,MONTH($J11=CI$5)),$E11/$R11*DAY($J11),IF(AND($O11<>"",$O11<CI$5),0,IF($K11="",$E11/$R11*AD11,IF(MONTH($K11)=MONTH(CI$5),$L11/$R11*AD11,IF(AND($K11<CI$5,(MONTH($K11)<>MONTH(CI$5))),$L11/$R11*AD11,$E11/$R11*AD11)))))) -> 17.355 | CJ11: =SUM(BX11:CI11) -> 231.4 | CK11: =+IF(P11<5,18,IF(AND(P11>=5,P11<10),19,IF(AND(P11>=10,P11<15),20,IF(AND(P11>=15,P11<20),21,0)))) -> 20 | CL11: =+CM11-CJ11 -> 0 | CM11: =IF(L11=0,E11,(L11-E11+E11)) -> 231.4
A12: 04020 | B12: NSUMBU KAYEMBE GIRESSE | C12: Receptionist | D12: =+VLOOKUP(A12,'[1]BDD-Avk Tx'!B:CE,82,0) -> 120 | E12: 231.4 | G12: 41153 | H12: =+IF(YEAR(G12)<YEAR($H$5),$H$4,G12) -> 45647 | I12: =+VLOOKUP(A12,'[1]BDD-Avk Tx'!B:BZ,77,0) -> CDI | J12: =+IF(I12="CDI",H12,H12+0) -> 45647 | P12: =DATEDIF(G12,$AD$6,"m")/12 -> 13.25 | Q12: 13 | R12: =SUM(S12:AD12) -> 20 | S12: =+IF(AND(AND($O12="",$P12>=10,MONTH($G12)=MONTH(S$5))),1.5+2,+IF(AND(AND($O12="",$P12>=5,MONTH($G12)=MONTH(S$5))),1.5+1,+IF(AND(AND($P12=5,$O12="",MONTH($G12)=MONTH(S$5))),1.5,+IF(AND($H12>S$5,MONTH($H12)=MONTH(S$5)),1.5/30*(S$4-DAY($H12)),+IF(AND(MONTH($H12)<MONTH(S$5),$O12=""),1.5,+IF(AND($H12=$S$5,$O12=""),1.5,IF($O12<S$5,0,IF(MONTH($O12)=MONTH(S$5),1.5/30*($O12-S$5),1.5)))))))) -> 1.5 | T12: =+IF(AND(AND($O12="",$P12>=10,MONTH($G12)=MONTH(T$5))),1.5+2,+IF(AND(AND($O12="",$P12>=5,MONTH($G12)=MONTH(T$5))),1.5+1,+IF(AND(AND($P12=5,$O12="",MONTH($G12)=MONTH(T$5))),1.5,+IF(AND($H12>T$5,MONTH($H12)=MONTH(T$5)),1.5/30*(T$4-DAY($H12)),+IF(AND(MONTH($H12)<MONTH(T$5),$O12=""),1.5,+IF(AND($H12=$S$5,$O12=""),1.5,IF($O12<T$5,0,IF(MONTH($O12)=MONTH(T$5),1.5/30*($O12-T$5),1.5)))))))) -> 1.5 | U12: =+IF(AND(AND($O12="",$P12>=10,MONTH($G12)=MONTH(U$5))),1.5+2,+IF(AND(AND($O12="",$P12>=5,MONTH($G12)=MONTH(U$5))),1.5+1,+IF(AND(AND($P12=5,$O12="",MONTH($G12)=MONTH(U$5))),1.5,+IF(AND($H12>U$5,MONTH($H12)=MONTH(U$5)),1.5/30*(U$4-DAY($H12)),+IF(AND(MONTH($H12)<MONTH(U$5),$O12=""),1.5,+IF(AND($H12=$S$5,$O12=""),1.5,IF($O12<U$5,0,IF(MONTH($O12)=MONTH(U$5),1.5/30*($O12-U$5),1.5)))))))) -> 1.5 | V12: =+IF(AND(AND($O12="",$P12>=10,MONTH($G12)=MONTH(V$5))),1.5+2,+IF(AND(AND($O12="",$P12>=5,MONTH($G12)=MONTH(V$5))),1.5+1,+IF(AND(AND($P12=5,$O12="",MONTH($G12)=MONTH(V$5))),1.5,+IF(AND($H12>V$5,MONTH($H12)=MONTH(V$5)),1.5/30*(V$4-DAY($H12)),+IF(AND(MONTH($H12)<MONTH(V$5),$O12=""),1.5,+IF(AND($H12=$S$5,$O12=""),1.5,IF($O12<V$5,0,IF(MONTH($O12)=MONTH(V$5),1.5/30*($O12-V$5),1.5)))))))) -> 1.5 | W12: =+IF(AND(AND($O12="",$P12>=10,MONTH($G12)=MONTH(W$5))),1.5+2,+IF(AND(AND($O12="",$P12>=5,MONTH($G12)=MONTH(W$5))),1.5+1,+IF(AND(AND($P12=5,$O12="",MONTH($G12)=MONTH(W$5))),1.5,+IF(AND($H12>W$5,MONTH($H12)=MONTH(W$5)),1.5/30*(W$4-DAY($H12)),+IF(AND(MONTH($H12)<MONTH(W$5),$O12=""),1.5,+IF(AND($H12=$S$5,$O12=""),1.5,IF($O12<W$5,0,IF(MONTH($O12)=MONTH(W$5),1.5/30*($O12-W$5),1.5)))))))) -> 1.5 | X12: =+IF(AND(AND($O12="",$P12>=10,MONTH($G12)=MONTH(X$5))),1.5+2,+IF(AND(AND($O12="",$P12>=5,MONTH($G12)=MONTH(X$5))),1.5+1,+IF(AND(AND($P12=5,$O12="",MONTH($G12)=MONTH(X$5))),1.5,+IF(AND($H12>X$5,MONTH($H12)=MONTH(X$5)),1.5/30*(X$4-DAY($H12)),+IF(AND(MONTH($H12)<MONTH(X$5),$O12=""),1.5,+IF(AND($H12=$S$5,$O12=""),1.5,IF($O12<X$5,0,IF(MONTH($O12)=MONTH(X$5),1.5/30*($O12-X$5),1.5)))))))) -> 1.5 | Y12: =+IF(AND(AND($O12="",$P12>=10,MONTH($G12)=MONTH(Y$5))),1.5+2,+IF(AND(AND($O12="",$P12>=5,MONTH($G12)=MONTH(Y$5))),1.5+1,+IF(AND(AND($P12=5,$O12="",MONTH($G12)=MONTH(Y$5))),1.5,+IF(AND($H12>Y$5,MONTH($H12)=MONTH(Y$5)),1.5/30*(Y$4-DAY($H12)),+IF(AND(MONTH($H12)<MONTH(Y$5),$O12=""),1.5,+IF(AND($H12=$S$5,$O12=""),1.5,IF($O12<Y$5,0,IF(MONTH($O12)=MONTH(Y$5),1.5/30*($O12-Y$5),1.5)))))))) -> 1.5 | Z12: =+IF(AND(AND($O12="",$P12>=10,MONTH($G12)=MONTH(Z$5))),1.5+2,+IF(AND(AND($O12="",$P12>=5,MONTH($G12)=MONTH(Z$5))),1.5+1,+IF(AND(AND($P12=5,$O12="",MONTH($G12)=MONTH(Z$5))),1.5,+IF(AND($H12>Z$5,MONTH($H12)=MONTH(Z$5)),1.5/30*(Z$4-DAY($H12)),+IF(AND(MONTH($H12)<MONTH(Z$5),$O12=""),1.5,+IF(AND($H12=$S$5,$O12=""),1.5,IF($O12<Z$5,0,IF(MONTH($O12)=MONTH(Z$5),1.5/30*($O12-Z$5),1.5)))))))) -> 1.5 | ... AD12: =+IF(AND(AND($O12="",$P12>=10,MONTH($G12)=MONTH(AD$5))),1.5+2,+IF(AND(AND($O12="",$P12>=5,MONTH($G12)=MONTH(AD$5))),1.5+1,+IF(AND(AND($P12=5,$O12="",MONTH($G12)=MONTH(AD$5))),1.5,+IF(AND($H12>AD$5,MONTH($H12)=MONTH(AD$5)),1.5/30*(AD$4-DAY($H12)),+IF(AND(MONTH($H12)<MONTH(AD$5),$O12=""),1.5,+IF(AND($H12=$S$5,$O12=""),1.5,IF($O12<AD$5,0,IF(MONTH($O12)=MONTH(AD$5),1.5/30*($O12-AD$5),1.5)))))))) -> 1.5 | AF12: =SUM(AG12:AR12) -> 7 | AG12: 7 | AH12: 0 | AI12: 0 | AS12: =+Q12+R12-AF12 -> 26 | AU12: 87.453846 | AV12: =SUM(AW12:BH12) -> 178 | AW12: =+IF($K12="",$E12/26*S12,IF(MONTH($K12)=MONTH(AW$5),$L12/26*S12,IF(AND($K12<AW$5,(MONTH($K12)<>MONTH(AW$5))),$L12/26*S12,$E12/26*S12))) -> 13.35 | AX12: =+IF($K12="",$E12/26*T12,IF(MONTH($K12)=MONTH(AX$5),$L12/26*T12,IF(AND($K12<AX$5,(MONTH($K12)<>MONTH(AX$5))),$L12/26*T12,$E12/26*T12))) -> 13.35 | AY12: =+IF($K12="",$E12/26*U12,IF(MONTH($K12)=MONTH(AY$5),$L12/26*U12,IF(AND($K12<AY$5,(MONTH($K12)<>MONTH(AY$5))),$L12/26*U12,$E12/26*U12))) -> 13.35 | AZ12: =+IF($K12="",$E12/26*V12,IF(MONTH($K12)=MONTH(AZ$5),$L12/26*V12,IF(AND($K12<AZ$5,(MONTH($K12)<>MONTH(AZ$5))),$L12/26*V12,$E12/26*V12))) -> 13.35 | BA12: =+IF($K12="",$E12/26*W12,IF(MONTH($K12)=MONTH(BA$5),$L12/26*W12,IF(AND($K12<BA$5,(MONTH($K12)<>MONTH(BA$5))),$L12/26*W12,$E12/26*W12))) -> 13.35 | BB12: =+IF($K12="",$E12/26*X12,IF(MONTH($K12)=MONTH(BB$5),$L12/26*X12,IF(AND($K12<BB$5,(MONTH($K12)<>MONTH(BB$5))),$L12/26*X12,$E12/26*X12))) -> 13.35 | BC12: =+IF($K12="",$E12/26*Y12,IF(MONTH($K12)=MONTH(BC$5),$L12/26*Y12,IF(AND($K12<BC$5,(MONTH($K12)<>MONTH(BC$5))),$L12/26*Y12,$E12/26*Y12))) -> 13.35 | BD12: =+IF($K12="",$E12/26*Z12,IF(MONTH($K12)=MONTH(BD$5),$L12/26*Z12,IF(AND($K12<BD$5,(MONTH($K12)<>MONTH(BD$5))),$L12/26*Z12,$E12/26*Z12))) -> 13.35 | ... BH12: =+IF($K12="",$E12/26*AD12,IF(MONTH($K12)=MONTH(BH$5),$L12/26*AD12,IF(AND($K12<BH$5,(MONTH($K12)<>MONTH(BH$5))),$L12/26*AD12,$E12/26*AD12))) -> 13.35 | BI12: =SUM(BJ12:BU12) -> -62.3 | BJ12: =(+IF($K12="",$E12/26*AG12,IF(MONTH($K12)=MONTH(BJ$5),$L12/26*AG12,IF(AND($K12<BJ$5,(MONTH($K12)<>MONTH(BJ$5))),$L12/26*AG12,$E12/26*AG12))))*-1 -> -62.3 | BK12: =(+IF($K12="",$E12/26*AH12,IF(MONTH($K12)=MONTH(BK$5),$L12/26*AH12,IF(AND($K12<BK$5,(MONTH($K12)<>MONTH(BK$5))),$L12/26*AH12,$E12/26*AH12))))*-1 -> 0 | BL12: =(+IF($K12="",$E12/26*AI12,IF(MONTH($K12)=MONTH(BL$5),$L12/26*AI12,IF(AND($K12<BL$5,(MONTH($K12)<>MONTH(BL$5))),$L12/26*AI12,$E12/26*AI12))))*-1 -> 0 | BM12: =(+IF($K12="",$E12/26*AJ12,IF(MONTH($K12)=MONTH(BM$5),$L12/26*AJ12,IF(AND($K12<BM$5,(MONTH($K12)<>MONTH(BM$5))),$L12/26*AJ12,$E12/26*AJ12))))*-1 -> 0 | BN12: =(+IF($K12="",$E12/26*AK12,IF(MONTH($K12)=MONTH(BN$5),$L12/26*AK12,IF(AND($K12<BN$5,(MONTH($K12)<>MONTH(BN$5))),$L12/26*AK12,$E12/26*AK12))))*-1 -> 0 | BO12: =(+IF($K12="",$E12/26*AL12,IF(MONTH($K12)=MONTH(BO$5),$L12/26*AL12,IF(AND($K12<BO$5,(MONTH($K12)<>MONTH(BO$5))),$L12/26*AL12,$E12/26*AL12))))*-1 -> 0 | BP12: =(+IF($K12="",$E12/26*AM12,IF(MONTH($K12)=MONTH(BP$5),$L12/26*AM12,IF(AND($K12<BP$5,(MONTH($K12)<>MONTH(BP$5))),$L12/26*AM12,$E12/26*AM12))))*-1 -> 0 | BQ12: =(+IF($K12="",$E12/26*AN12,IF(MONTH($K12)=MONTH(BQ$5),$L12/26*AN12,IF(AND($K12<BQ$5,(MONTH($K12)<>MONTH(BQ$5))),$L12/26*AN12,$E12/26*AN12))))*-1 -> 0 | ... BU12: =(+IF($K12="",$E12/26*AR12,IF(MONTH($K12)=MONTH(BU$5),$L12/26*AR12,IF(AND($K12<BU$5,(MONTH($K12)<>MONTH(BU$5))),$L12/26*AR12,$E12/26*AR12))))*-1 -> 0 | BV12: =+AU12+AV12+BI12 -> 203.15385 | BX12: =+IF(AND($J12>BX$5,MONTH($J12<>BX$5)),0,+IF(AND($J12>BX$5,MONTH($J12=BX$5)),$E12/$R12*DAY($J12),IF(AND($O12<>"",$O12<BX$5),0,IF($K12="",$E12/$R12*S12,IF(MONTH($K12)=MONTH(BX$5),$L12/$R12*S12,IF(AND($K12<BX$5,(MONTH($K12)<>MONTH(BX$5))),$L12/$R12*S12,$E12/$R12*S12)))))) -> 17.355 | BY12: =+IF(AND($J12>BY$5,MONTH($J12<>BY$5)),0,+IF(AND($J12>BY$5,MONTH($J12=BY$5)),$E12/$R12*DAY($J12),IF(AND($O12<>"",$O12<BY$5),0,IF($K12="",$E12/$R12*T12,IF(MONTH($K12)=MONTH(BY$5),$L12/$R12*T12,IF(AND($K12<BY$5,(MONTH($K12)<>MONTH(BY$5))),$L12/$R12*T12,$E12/$R12*T12)))))) -> 17.355 | BZ12: =+IF(AND($J12>BZ$5,MONTH($J12<>BZ$5)),0,+IF(AND($J12>BZ$5,MONTH($J12=BZ$5)),$E12/$R12*DAY($J12),IF(AND($O12<>"",$O12<BZ$5),0,IF($K12="",$E12/$R12*U12,IF(MONTH($K12)=MONTH(BZ$5),$L12/$R12*U12,IF(AND($K12<BZ$5,(MONTH($K12)<>MONTH(BZ$5))),$L12/$R12*U12,$E12/$R12*U12)))))) -> 17.355 | CA12: =+IF(AND($J12>CA$5,MONTH($J12<>CA$5)),0,+IF(AND($J12>CA$5,MONTH($J12=CA$5)),$E12/$R12*DAY($J12),IF(AND($O12<>"",$O12<CA$5),0,IF($K12="",$E12/$R12*V12,IF(MONTH($K12)=MONTH(CA$5),$L12/$R12*V12,IF(AND($K12<CA$5,(MONTH($K12)<>MONTH(CA$5))),$L12/$R12*V12,$E12/$R12*V12)))))) -> 17.355 | CB12: =+IF(AND($J12>CB$5,MONTH($J12<>CB$5)),0,+IF(AND($J12>CB$5,MONTH($J12=CB$5)),$E12/$R12*DAY($J12),IF(AND($O12<>"",$O12<CB$5),0,IF($K12="",$E12/$R12*W12,IF(MONTH($K12)=MONTH(CB$5),$L12/$R12*W12,IF(AND($K12<CB$5,(MONTH($K12)<>MONTH(CB$5))),$L12/$R12*W12,$E12/$R12*W12)))))) -> 17.355 | CC12: =+IF(AND($J12>CC$5,MONTH($J12<>CC$5)),0,+IF(AND($J12>CC$5,MONTH($J12=CC$5)),$E12/$R12*DAY($J12),IF(AND($O12<>"",$O12<CC$5),0,IF($K12="",$E12/$R12*X12,IF(MONTH($K12)=MONTH(CC$5),$L12/$R12*X12,IF(AND($K12<CC$5,(MONTH($K12)<>MONTH(CC$5))),$L12/$R12*X12,$E12/$R12*X12)))))) -> 17.355 | CD12: =+IF(AND($J12>CD$5,MONTH($J12<>CD$5)),0,+IF(AND($J12>CD$5,MONTH($J12=CD$5)),$E12/$R12*DAY($J12),IF(AND($O12<>"",$O12<CD$5),0,IF($K12="",$E12/$R12*Y12,IF(MONTH($K12)=MONTH(CD$5),$L12/$R12*Y12,IF(AND($K12<CD$5,(MONTH($K12)<>MONTH(CD$5))),$L12/$R12*Y12,$E12/$R12*Y12)))))) -> 17.355 | CE12: =+IF(AND($J12>CE$5,MONTH($J12<>CE$5)),0,+IF(AND($J12>CE$5,MONTH($J12=CE$5)),$E12/$R12*DAY($J12),IF(AND($O12<>"",$O12<CE$5),0,IF($K12="",$E12/$R12*Z12,IF(MONTH($K12)=MONTH(CE$5),$L12/$R12*Z12,IF(AND($K12<CE$5,(MONTH($K12)<>MONTH(CE$5))),$L12/$R12*Z12,$E12/$R12*Z12)))))) -> 17.355 | ... CI12: =+IF(AND($J12>CI$5,MONTH($J12<>CI$5)),0,+IF(AND($J12>CI$5,MONTH($J12=CI$5)),$E12/$R12*DAY($J12),IF(AND($O12<>"",$O12<CI$5),0,IF($K12="",$E12/$R12*AD12,IF(MONTH($K12)=MONTH(CI$5),$L12/$R12*AD12,IF(AND($K12<CI$5,(MONTH($K12)<>MONTH(CI$5))),$L12/$R12*AD12,$E12/$R12*AD12)))))) -> 17.355 | CJ12: =SUM(BX12:CI12) -> 231.4 | CK12: =+IF(P12<5,18,IF(AND(P12>=5,P12<10),19,IF(AND(P12>=10,P12<15),20,IF(AND(P12>=15,P12<20),21,0)))) -> 20 | CL12: =+CM12-CJ12 -> 0 | CM12: =IF(L12=0,E12,(L12-E12+E12)) -> 231.4
